#VRML_SIM R2023b utf8

EXTERNPROTO "https://raw.githubusercontent.com/cyberbotics/webots/R2023b/projects/objects/backgrounds/protos/TexturedBackgroundLight.proto"
EXTERNPROTO "https://raw.githubusercontent.com/cyberbotics/webots/R2023b/projects/objects/backgrounds/protos/TexturedBackground.proto"
EXTERNPROTO "https://raw.githubusercontent.com/cyberbotics/webots/R2023b/projects/objects/floors/protos/RectangleArena.proto"

WorldInfo {
}
Viewpoint {
  fieldOfView 0.785397
  orientation -0.16340075975237964 -0.12283002853610445 0.9788835353616715 4.410359700281999
  position 0.0834690914526116 0.23437771860636872 0.2083650190896674
}
TexturedBackgroundLight {
}
TexturedBackground {
}
RectangleArena {
  floorSize 5 5
}
Robot {
  translation 0 0 0.14
  children [
    DEF LeftLeg1 Solid {
      children [
        HingeJoint {
          jointParameters HingeJointParameters {
          }
          device [
            DEF LeftLeg1_Joint1_Motor1 RotationalMotor {
              name "LeftLeg1_Joint1_Motor1"
            }
          ]
          endPoint Solid {
            translation 0.07 0.027 -0.006
            rotation 0 0 1 3.14159
            children [
              DEF LeftLeg1_leg2 Shape {
                appearance PBRAppearance {
                  metalness 0
                }
                geometry Mesh {
                  url [
                    "../stl/leg3.stl"
                  ]
                }
              }
              DEF LeftLeg1_leg2 Solid {
                name "LeftLeg1_leg2"
              }
            ]
          }
        }
        DEF LeftLeg1_Joint1 Solid {
          translation 0.0282844 0.0282844 -0.0099999
          rotation 2.346409999992433e-06 -9.719149999968655e-07 0.999999999996775 -2.3561953071795863
          children [
            Shape {
              appearance PBRAppearance {
                baseColor 0 0.333333 1
                metalness 0
              }
              geometry Mesh {
                url [
                  "../stl/SG90.stl"
                ]
              }
            }
          ]
          name "LeftLeg1_Joint1"
        }
      ]
      name "LeftLeg1"
    }
    DEF BODY Shape {
      appearance PBRAppearance {
        metalness 0
      }
      geometry Mesh {
        url [
          "../stl/body.stl"
        ]
      }
    }
  ]
  name "S1"
}
